Traceback (most recent call last):
  File "/opt/hostedtoolcache/Python/3.13.5/x64/lib/python3.13/site-packages/jupyter_core/utils/__init__.py", line 154, in wrapped
    asyncio.get_running_loop()
    ~~~~~~~~~~~~~~~~~~~~~~~~^^
RuntimeError: no running event loop

During handling of the above exception, another exception occurred:

Traceback (most recent call last):
  File "/opt/hostedtoolcache/Python/3.13.5/x64/lib/python3.13/site-packages/jupyter_cache/executors/utils.py", line 58, in single_nb_execution
    executenb(
    ~~~~~~~~~^
        nb,
        ^^^
    ...<4 lines>...
        **kwargs,
        ^^^^^^^^^
    )
    ^
  File "/opt/hostedtoolcache/Python/3.13.5/x64/lib/python3.13/site-packages/nbclient/client.py", line 1319, in execute
    return NotebookClient(nb=nb, resources=resources, km=km, **kwargs).execute()
           ~~~~~~~~~~~~~~~~~~~~~~~~~~~~~~~~~~~~~~~~~~~~~~~~~~~~~~~~~~~~~~~~~~~^^
  File "/opt/hostedtoolcache/Python/3.13.5/x64/lib/python3.13/site-packages/jupyter_core/utils/__init__.py", line 158, in wrapped
    return loop.run_until_complete(inner)
           ~~~~~~~~~~~~~~~~~~~~~~~^^^^^^^
  File "/opt/hostedtoolcache/Python/3.13.5/x64/lib/python3.13/asyncio/base_events.py", line 725, in run_until_complete
    return future.result()
           ~~~~~~~~~~~~~^^
  File "/opt/hostedtoolcache/Python/3.13.5/x64/lib/python3.13/site-packages/nbclient/client.py", line 709, in async_execute
    await self.async_execute_cell(
        cell, index, execution_count=self.code_cells_executed + 1
    )
  File "/opt/hostedtoolcache/Python/3.13.5/x64/lib/python3.13/site-packages/nbclient/client.py", line 1062, in async_execute_cell
    await self._check_raise_for_error(cell, cell_index, exec_reply)
  File "/opt/hostedtoolcache/Python/3.13.5/x64/lib/python3.13/site-packages/nbclient/client.py", line 918, in _check_raise_for_error
    raise CellExecutionError.from_cell_and_msg(cell, exec_reply_content)
nbclient.exceptions.CellExecutionError: An error occurred while executing the following cell:
------------------
from loadest_gp.providers import usgs

# download covariates (daily streamflow)
daily = usgs.get_daily(site=site, start_date=start_date, end_date=end_date)

# download target (concentration)
samples = usgs.get_samples(site=site, 
                           start_date=start_date, 
                           end_date=end_date, 
                           characteristic=characteristic, 
                           fraction=fraction)

samples
------------------


Traceback [36m(most recent call last)[39m:

  File [92m/opt/hostedtoolcache/Python/3.13.5/x64/lib/python3.13/site-packages/IPython/core/interactiveshell.py:3699[39m in [95mrun_code[39m
    exec(code_obj, self.user_global_ns, self.user_ns)

  Cell [92mIn[4][39m[92m, line 1[39m
    from loadest_gp.providers import usgs

  File [92m~/work/discontinuum/discontinuum/src/loadest_gp/__init__.py:15[39m
    exec(f"from .models.gpytorch import {name}")

  File [92m<string>:1[39m

[36m  [39m[36mFile [39m[32m~/work/discontinuum/discontinuum/src/loadest_gp/models/gpytorch.py:4[39m
[31m    [39m[31mfrom discontinuum.engines.gpytorch import MarginalGPyTorch[39m

  [36mFile [39m[32m~/work/discontinuum/discontinuum/src/discontinuum/engines/gpytorch.py:123[39m
[31m    [39m[31melif optimizer == "lbfgs":[39m
    ^
[31mSyntaxError[39m[31m:[39m invalid syntax


